<?xml version="1.0" ?>
<robot name="BadBot" xmlns:xacro="http://www.ros.org/wiki/xacro">

<xacro:include filename="$(find BadBot_description)/urdf/materials.xacro" />
<xacro:include filename="$(find BadBot_description)/urdf/BadBot.trans" />

<xacro:include filename="$(find BadBot_description)/gazebo/BadBot_materials.gazebo" />
<xacro:include filename="$(find BadBot_description)/gazebo/BadBot_physics.gazebo" />
<xacro:include filename="$(find BadBot_description)/gazebo/BadBot_plugins.gazebo" />

<link name="base_link">
  <inertial>
    <origin xyz="-0.016271579372150194 0.14227699615361108 0.13718460738785923" rpy="0 0 0"/>
    <mass value="28.94724121287408"/>
    <inertia ixx="0.483788" iyy="0.452084" izz="0.900633" ixy="0.0" iyz="-0.002009" ixz="0.0"/>
  </inertial>
  <visual>
    <origin xyz="0 0 0" rpy="0 0 0"/>
    <geometry>
      <mesh filename="package://BadBot_description/meshes/base_link.stl" scale="0.001 0.001 0.001"/>
    </geometry>
    <material name="silver"/>
  </visual>
  <collision>
    <origin xyz="0 0 0" rpy="0 0 0"/>
    <geometry>
      <mesh filename="package://BadBot_description/meshes/base_link.stl" scale="0.001 0.001 0.001"/>
    </geometry>
  </collision>
</link>

<link name="caster_wheel_1_1_1">
  <inertial>
    <origin xyz="4.2062784975580025e-07 1.9035339363093762e-07 -1.0802124120190548e-07" rpy="0 0 0"/>
    <mass value="1.4008361642356892"/>
    <inertia ixx="0.000686" iyy="0.000686" izz="0.000686" ixy="-0.0" iyz="-0.0" ixz="-0.0"/>
  </inertial>
  <visual>
    <origin xyz="0.016272 -0.029802 -0.093867" rpy="0 0 0"/>
    <geometry>
      <mesh filename="package://BadBot_description/meshes/caster_wheel_1_1_1.stl" scale="0.001 0.001 0.001"/>
    </geometry>
    <material name="silver"/>
  </visual>
  <collision>
    <origin xyz="0.016272 -0.029802 -0.093867" rpy="0 0 0"/>
    <geometry>
      <mesh filename="package://BadBot_description/meshes/caster_wheel_1_1_1.stl" scale="0.001 0.001 0.001"/>
    </geometry>
  </collision>
</link>

<link name="right_wheel_2_1_1">
  <inertial>
    <origin xyz="4.206278496621252e-07 -1.21080121928685e-07 -1.0802128527775956e-07" rpy="0 0 0"/>
    <mass value="0.38540002551002456"/>
    <inertia ixx="0.000496" iyy="0.000299" izz="0.000299" ixy="-0.0" iyz="-0.0" ixz="-0.0"/>
  </inertial>
  <visual>
    <origin xyz="-0.133728 -0.221391 -0.108867" rpy="0 0 0"/>
    <geometry>
      <mesh filename="package://BadBot_description/meshes/right_wheel_2_1_1.stl" scale="0.001 0.001 0.001"/>
    </geometry>
    <material name="silver"/>
  </visual>
  <collision>
    <origin xyz="-0.133728 -0.221391 -0.108867" rpy="0 0 0"/>
    <geometry>
      <mesh filename="package://BadBot_description/meshes/right_wheel_2_1_1.stl" scale="0.001 0.001 0.001"/>
    </geometry>
  </collision>
</link>

<link name="left_wheel_1_1_1">
  <inertial>
    <origin xyz="4.2062784980090306e-07 -1.2108012190092943e-07 -1.0802128526388177e-07" rpy="0 0 0"/>
    <mass value="0.38540002551002467"/>
    <inertia ixx="0.000496" iyy="0.000299" izz="0.000299" ixy="-0.0" iyz="0.0" ixz="0.0"/>
  </inertial>
  <visual>
    <origin xyz="0.166272 -0.221391 -0.108867" rpy="0 0 0"/>
    <geometry>
      <mesh filename="package://BadBot_description/meshes/left_wheel_1_1_1.stl" scale="0.001 0.001 0.001"/>
    </geometry>
    <material name="silver"/>
  </visual>
  <collision>
    <origin xyz="0.166272 -0.221391 -0.108867" rpy="0 0 0"/>
    <geometry>
      <mesh filename="package://BadBot_description/meshes/left_wheel_1_1_1.stl" scale="0.001 0.001 0.001"/>
    </geometry>
  </collision>
</link>

<link name="r_wheel_shaft_2_1_1">
  <inertial>
    <origin xyz="-0.04749957937215024 -1.2108012187317385e-07 -1.080212411880277e-07" rpy="0 0 0"/>
    <mass value="0.23876104167282425"/>
    <inertia ixx="1.2e-05" iyy="0.000186" izz="0.000186" ixy="0.0" iyz="-0.0" ixz="0.0"/>
  </inertial>
  <visual>
    <origin xyz="-0.181228 -0.221391 -0.108867" rpy="0 0 0"/>
    <geometry>
      <mesh filename="package://BadBot_description/meshes/r_wheel_shaft_2_1_1.stl" scale="0.001 0.001 0.001"/>
    </geometry>
    <material name="silver"/>
  </visual>
  <collision>
    <origin xyz="-0.181228 -0.221391 -0.108867" rpy="0 0 0"/>
    <geometry>
      <mesh filename="package://BadBot_description/meshes/r_wheel_shaft_2_1_1.stl" scale="0.001 0.001 0.001"/>
    </geometry>
  </collision>
</link>

<link name="l_wheel_shaft_1_1_1">
  <inertial>
    <origin xyz="0.047500420627849954 -1.2108012209521846e-07 -1.0802124131292778e-07" rpy="0 0 0"/>
    <mass value="0.23876104167282444"/>
    <inertia ixx="1.2e-05" iyy="0.000186" izz="0.000186" ixy="0.0" iyz="-0.0" ixz="0.0"/>
  </inertial>
  <visual>
    <origin xyz="0.213772 -0.221391 -0.108867" rpy="0 0 0"/>
    <geometry>
      <mesh filename="package://BadBot_description/meshes/l_wheel_shaft_1_1_1.stl" scale="0.001 0.001 0.001"/>
    </geometry>
    <material name="silver"/>
  </visual>
  <collision>
    <origin xyz="0.213772 -0.221391 -0.108867" rpy="0 0 0"/>
    <geometry>
      <mesh filename="package://BadBot_description/meshes/l_wheel_shaft_1_1_1.stl" scale="0.001 0.001 0.001"/>
    </geometry>
  </collision>
</link>

<joint name="Rigid12" type="fixed">
  <origin xyz="-0.016272 0.029802 0.093867" rpy="0 0 0"/>
  <parent link="base_link"/>
  <child link="caster_wheel_1_1_1"/>
</joint>

<joint name="Rev13" type="continuous">
  <origin xyz="-0.0475 0.0 0.0" rpy="0 0 0"/>
  <parent link="r_wheel_shaft_2_1_1"/>
  <child link="right_wheel_2_1_1"/>
  <axis xyz="-1.0 0.0 0.0"/>
</joint>

<joint name="Rev14" type="continuous">
  <origin xyz="0.0475 0.0 0.0" rpy="0 0 0"/>
  <parent link="l_wheel_shaft_1_1_1"/>
  <child link="left_wheel_1_1_1"/>
  <axis xyz="-1.0 0.0 0.0"/>
</joint>

<joint name="Rigid15" type="fixed">
  <origin xyz="0.181228 0.221391 0.108867" rpy="0 0 0"/>
  <parent link="base_link"/>
  <child link="r_wheel_shaft_2_1_1"/>
</joint>

<joint name="Rigid16" type="fixed">
  <origin xyz="-0.213772 0.221391 0.108867" rpy="0 0 0"/>
  <parent link="base_link"/>
  <child link="l_wheel_shaft_1_1_1"/>
</joint>

</robot>
