<?xml version="1.0" ?>
<!-- =================================================================================== -->
<!-- |    This document was autogenerated by xacro from BadBot.xacro                   | -->
<!-- |    EDITING THIS FILE BY HAND IS NOT RECOMMENDED                                 | -->
<!-- =================================================================================== -->
<robot name="BadBot">
  <material name="silver">
    <color rgba="0.700 0.700 0.700 1.000"/>
  </material>
  <transmission name="Rev7_tran">
    <type>transmission_interface/SimpleTransmission</type>
    <joint name="Rev7">
      <hardwareInterface>hardware_interface/EffortJointInterface</hardwareInterface>
    </joint>
    <actuator name="Rev7_actr">
      <hardwareInterface>hardware_interface/EffortJointInterface</hardwareInterface>
      <mechanicalReduction>1</mechanicalReduction>
    </actuator>
  </transmission>
  <transmission name="Rev8_tran">
    <type>transmission_interface/SimpleTransmission</type>
    <joint name="Rev8">
      <hardwareInterface>hardware_interface/EffortJointInterface</hardwareInterface>
    </joint>
    <actuator name="Rev8_actr">
      <hardwareInterface>hardware_interface/EffortJointInterface</hardwareInterface>
      <mechanicalReduction>1</mechanicalReduction>
    </actuator>
  </transmission>
  <transmission name="Rev10_tran">
    <type>transmission_interface/SimpleTransmission</type>
    <joint name="Rev10">
      <hardwareInterface>hardware_interface/EffortJointInterface</hardwareInterface>
    </joint>
    <actuator name="Rev10_actr">
      <hardwareInterface>hardware_interface/EffortJointInterface</hardwareInterface>
      <mechanicalReduction>1</mechanicalReduction>
    </actuator>
  </transmission>
  <gazebo reference="base_link">
    <material>Gazebo/Blue</material>
  </gazebo>
  <gazebo reference="caster_wheel_1">
    <material>Gazebo/Grey</material>
  </gazebo>
  <gazebo reference="right_wheel_1">
    <material>Gazebo/Black</material>
  </gazebo>
  <gazebo reference="right_wheel_axle_1">
    <material>Gazebo/Grey</material>
  </gazebo>
  <gazebo reference="left_wheel_1">
    <material>Gazebo/Black</material>
  </gazebo>
  <gazebo reference="_left_wheel_axle_1">
    <material>Gazebo/Grey</material>
  </gazebo>
  <gazebo reference="lidar_v1_1">
    <material>Gazebo/Red</material>
  </gazebo>
  <gazebo reference="base_link">
    <mu1>0.2</mu1>
    <mu2>0.2</mu2>
    <selfCollide>true</selfCollide>
    <gravity>true</gravity>
  </gazebo>
  <gazebo reference="caster_wheel_">
    <mu1>0.1</mu1>
    <mu2>0.1</mu2>
    <selfCollide>true</selfCollide>
  </gazebo>
  <gazebo reference="right_wheel_1">
    <mu1>1500</mu1>
    <mu2>1500</mu2>
    <selfCollide>true</selfCollide>
  </gazebo>
  <gazebo reference="right_wheel_axle_1">
    <mu1>0.2</mu1>
    <mu2>0.2</mu2>
    <selfCollide>true</selfCollide>
  </gazebo>
  <gazebo reference="left_wheel_1">
    <mu1>1500</mu1>
    <mu2>1500</mu2>
    <selfCollide>true</selfCollide>
  </gazebo>
  <gazebo reference="_left_wheel_axle_1">
    <mu1>0.2</mu1>
    <mu2>0.2</mu2>
    <selfCollide>true</selfCollide>
  </gazebo>
  <gazebo reference="lidar_v1_1">
    <mu1>0.2</mu1>
    <mu2>0.2</mu2>
    <selfCollide>true</selfCollide>
  </gazebo>
  <!--################# ROS CONTROL ###################-->
  <gazebo>
    <plugin filename="libgazebo_ros_control.so" name="control"/>
  </gazebo>
  <!--################# DIFFERENTIAL DRIVE ###################-->
  <gazebo>
    <plugin filename="libgazebo_ros_diff_drive.so" name="differential_drive_controller">
      <!-- Plugin update rate in Hz -->
      <updateRate>10</updateRate>
      <!-- Name of left joint, defaults to `left_joint` -->
      <leftJoint>Rev10</leftJoint>
      <!-- Name of right joint, defaults to `right_joint` -->
      <rightJoint>Rev8</rightJoint>
      <!-- Wheel acceleration, in rad/s^2, defaults to 0.0 rad/s^2 -->
      <wheelAcceleration>1.0</wheelAcceleration>
      <!-- Maximum torque which the wheels can produce, in Nm, defaults to 5 Nm -->
      <wheelTorque>20</wheelTorque>
      <!-- Topic to receive geometry_msgs/Twist message commands, defaults to `cmd_vel` -->
      <commandTopic>cmd_vel</commandTopic>
      <!-- Topic to publish nav_msgs/Odometry messages, defaults to `odom` -->
      <odometryTopic>odom</odometryTopic>
      <!-- Odometry frame, defaults to `odom` -->
      <odometryFrame>odom</odometryFrame>
      <!-- Robot frame to calculate odometry from, defaults to `base_footprint` -->
      <robotBaseFrame>base_link</robotBaseFrame>
      <!-- Odometry source, 0 for ENCODER, 1 for WORLD, defaults to WORLD -->
      <odometrySource>1</odometrySource>
      <!-- Set to true to publish transforms for the wheel links, defaults to false -->
      <publishWheelTF>true</publishWheelTF>
      <!-- Set to true to publish transforms for the odometry, defaults to true -->
      <publishOdom>true</publishOdom>
      <!-- Set to true to publish sensor_msgs/JointState on /joint_states for the wheel joints, defaults to false -->
      <publishWheelJointState>true</publishWheelJointState>
      <!--Set to true to swap right and left wheels, defaults to true -->
      <legacyMode>false</legacyMode>
    </plugin>
  </gazebo>
  <!--################# LIDAR PLUGIN ###################-->
  <gazebo reference="lidar_v1_1">
    <sensor name="ydlidar" type="ray">
      <pose>0 0 0 0 0 0</pose>
      <visualize>true</visualize>
      <update_rate>10</update_rate>
      <ray>
        <scan>
          <horizontal>
            <samples>720</samples>
            <resolution>1</resolution>
            <min_angle>-3.14159</min_angle>
            <max_angle>3.14159</max_angle>
          </horizontal>
        </scan>
        <range>
          <min>0.55</min>
          <max>8.0</max>
          <resolution>0.01</resolution>
        </range>
        <noise>
          <type>gaussian</type>
          <!-- Noise parameters based on published spec for Hokuyo laser
               achieving "+-30mm" accuracy at range < 10m.  A mean of 0.0m and
               stddev of 0.01m will put 99.7% of samples within 0.03m of the true
               reading. -->
          <mean>0.0</mean>
          <stddev>0.01</stddev>
        </noise>
      </ray>
      <plugin filename="libgazebo_ros_laser.so" name="gazebo_ros_head_hokuyo_controller">
        <topicName>/scan</topicName>
        <frameName>lidar_v1_1</frameName>
      </plugin>
    </sensor>
  </gazebo>
  <link name="base_link">
    <inertial>
      <origin rpy="0 0 0" xyz="-0.016271579372150208 0.1417094158489788 0.1370115013532809"/>
      <mass value="28.855052709016757"/>
      <inertia ixx="0.480495" ixy="0.0" ixz="0.0" iyy="0.451805" iyz="-0.001119" izz="0.897614"/>
    </inertial>
    <visual>
      <origin rpy="0 0 0" xyz="0 0 0"/>
      <geometry>
        <mesh filename="package://BadBot_description/meshes/base_link.stl" scale="0.001 0.001 0.001"/>
      </geometry>
      <material name="silver"/>
    </visual>
    <collision>
      <origin rpy="0 0 0" xyz="0 0 0"/>
      <geometry>
        <mesh filename="package://BadBot_description/meshes/base_link.stl" scale="0.001 0.001 0.001"/>
      </geometry>
    </collision>
  </link>
  <link name="caster_wheel_1">
    <inertial>
      <origin rpy="0 0 0" xyz="4.2062784975580025e-07 1.9035339363093762e-07 -1.0802124120190548e-07"/>
      <mass value="1.4008361642356892"/>
      <inertia ixx="0.000686" ixy="-0.0" ixz="-0.0" iyy="0.000686" iyz="-0.0" izz="0.000686"/>
    </inertial>
    <visual>
      <origin rpy="0 0 0" xyz="0.016272 -0.029802 -0.093867"/>
      <geometry>
        <mesh filename="package://BadBot_description/meshes/caster_wheel_1.stl" scale="0.001 0.001 0.001"/>
      </geometry>
      <material name="silver"/>
    </visual>
    <collision>
      <origin rpy="0 0 0" xyz="0.016272 -0.029802 -0.093867"/>
      <geometry>
        <mesh filename="package://BadBot_description/meshes/caster_wheel_1.stl" scale="0.001 0.001 0.001"/>
      </geometry>
    </collision>
  </link>
  <link name="right_wheel_1">
    <inertial>
      <origin rpy="0 0 0" xyz="4.206278496621252e-07 -1.21080121928685e-07 -1.0802128527775956e-07"/>
      <mass value="0.38540002551002456"/>
      <inertia ixx="0.000496" ixy="-0.0" ixz="-0.0" iyy="0.000299" iyz="-0.0" izz="0.000299"/>
    </inertial>
    <visual>
      <origin rpy="0 0 0" xyz="-0.133728 -0.221391 -0.108867"/>
      <geometry>
        <mesh filename="package://BadBot_description/meshes/right_wheel_1.stl" scale="0.001 0.001 0.001"/>
      </geometry>
      <material name="silver"/>
    </visual>
    <collision>
      <origin rpy="0 0 0" xyz="-0.133728 -0.221391 -0.108867"/>
      <geometry>
        <mesh filename="package://BadBot_description/meshes/right_wheel_1.stl" scale="0.001 0.001 0.001"/>
      </geometry>
    </collision>
  </link>
  <link name="right_wheel_axle_1">
    <inertial>
      <origin rpy="0 0 0" xyz="-0.04749957937215024 -1.2108012187317385e-07 -1.080212411880277e-07"/>
      <mass value="0.23876104167282425"/>
      <inertia ixx="1.2e-05" ixy="0.0" ixz="0.0" iyy="0.000186" iyz="-0.0" izz="0.000186"/>
    </inertial>
    <visual>
      <origin rpy="0 0 0" xyz="-0.181228 -0.221391 -0.108867"/>
      <geometry>
        <mesh filename="package://BadBot_description/meshes/right_wheel_axle_1.stl" scale="0.001 0.001 0.001"/>
      </geometry>
      <material name="silver"/>
    </visual>
    <collision>
      <origin rpy="0 0 0" xyz="-0.181228 -0.221391 -0.108867"/>
      <geometry>
        <mesh filename="package://BadBot_description/meshes/right_wheel_axle_1.stl" scale="0.001 0.001 0.001"/>
      </geometry>
    </collision>
  </link>
  <link name="left_wheel_1">
    <inertial>
      <origin rpy="0 0 0" xyz="4.2062784980090306e-07 -1.2108012190092943e-07 -1.0802128526388177e-07"/>
      <mass value="0.38540002551002467"/>
      <inertia ixx="0.000496" ixy="-0.0" ixz="0.0" iyy="0.000299" iyz="0.0" izz="0.000299"/>
    </inertial>
    <visual>
      <origin rpy="0 0 0" xyz="0.166272 -0.221391 -0.108867"/>
      <geometry>
        <mesh filename="package://BadBot_description/meshes/left_wheel_1.stl" scale="0.001 0.001 0.001"/>
      </geometry>
      <material name="silver"/>
    </visual>
    <collision>
      <origin rpy="0 0 0" xyz="0.166272 -0.221391 -0.108867"/>
      <geometry>
        <mesh filename="package://BadBot_description/meshes/left_wheel_1.stl" scale="0.001 0.001 0.001"/>
      </geometry>
    </collision>
  </link>
  <link name="_left_wheel_axle_1">
    <inertial>
      <origin rpy="0 0 0" xyz="-0.04749957937215003 -1.2108012209521846e-07 -1.0802124131292778e-07"/>
      <mass value="0.23876104167282444"/>
      <inertia ixx="1.2e-05" ixy="0.0" ixz="0.0" iyy="0.000186" iyz="-0.0" izz="0.000186"/>
    </inertial>
    <visual>
      <origin rpy="0 0 0" xyz="0.118772 -0.221391 -0.108867"/>
      <geometry>
        <mesh filename="package://BadBot_description/meshes/_left_wheel_axle_1.stl" scale="0.001 0.001 0.001"/>
      </geometry>
      <material name="silver"/>
    </visual>
    <collision>
      <origin rpy="0 0 0" xyz="0.118772 -0.221391 -0.108867"/>
      <geometry>
        <mesh filename="package://BadBot_description/meshes/_left_wheel_axle_1.stl" scale="0.001 0.001 0.001"/>
      </geometry>
    </collision>
  </link>
  <link name="lidar_v1_1">
    <inertial>
      <origin rpy="0 0 0" xyz="-0.004865441389214329 0.1410900178145767 0.016766645484714182"/>
      <mass value="0.3543299620873657"/>
      <inertia ixx="0.000474" ixy="-2.3e-05" ixz="3e-06" iyy="0.000229" iyz="3.1e-05" izz="0.000616"/>
    </inertial>
    <visual>
      <origin rpy="0 0 0" xyz="0.016272 -0.146391 -0.178867"/>
      <geometry>
        <mesh filename="package://BadBot_description/meshes/lidar_v1_1.stl" scale="0.001 0.001 0.001"/>
      </geometry>
      <material name="silver"/>
    </visual>
    <collision>
      <origin rpy="0 0 0" xyz="0.016272 -0.146391 -0.178867"/>
      <geometry>
        <mesh filename="package://BadBot_description/meshes/lidar_v1_1.stl" scale="0.001 0.001 0.001"/>
      </geometry>
    </collision>
  </link>
  <joint name="Rev7" type="continuous">
    <origin rpy="0 0 0" xyz="-0.016272 0.029802 0.093867"/>
    <parent link="base_link"/>
    <child link="caster_wheel_1"/>
    <axis xyz="0.0 0.0 -1.0"/>
  </joint>
  <joint name="Rev8" type="continuous">
    <origin rpy="0 0 0" xyz="-0.0475 0.0 0.0"/>
    <parent link="right_wheel_axle_1"/>
    <child link="right_wheel_1"/>
    <axis xyz="-1.0 0.0 0.0"/>
  </joint>
  <joint name="Rigid9" type="fixed">
    <origin rpy="0 0 0" xyz="0.181228 0.221391 0.108867"/>
    <parent link="base_link"/>
    <child link="right_wheel_axle_1"/>
  </joint>
  <joint name="Rev10" type="continuous">
    <origin rpy="0 0 0" xyz="-0.0475 0.0 0.0"/>
    <parent link="_left_wheel_axle_1"/>
    <child link="left_wheel_1"/>
    <axis xyz="-1.0 0.0 0.0"/>
  </joint>
  <joint name="Rigid11" type="fixed">
    <origin rpy="0 0 0" xyz="-0.118772 0.221391 0.108867"/>
    <parent link="base_link"/>
    <child link="_left_wheel_axle_1"/>
  </joint>
  <joint name="Rigid12" type="fixed">
    <origin rpy="0 0 0" xyz="-0.016272 0.146391 0.178867"/>
    <parent link="base_link"/>
    <child link="lidar_v1_1"/>
  </joint>
</robot>
